Workbook

Sheet 辞書一覧
A1: 福祉用具 ユーザー辞書（Google日本語入力用）統合版 公開用
A2: 作成日：2026年10月05日 登録数：618件（うち選定理由・提案理由・留意事項・ケアマネージャーとの相談記録・モニタリング・相談内容 397件、今回追加 164件） 「文字数」「判定」は自動計算です。言葉を書き換えたら判定が「OK」（100文字以内）か確認してください。
A3: ※公開用のため、人名・住所・メールアドレス・社内関係者名などの個人情報を含む登録は除いています。
A4: No. | B4: 分類 | C4: 小分類 | D4: よみ | E4: 登録する言葉 | F4: 品詞 | G4: 文字数 | H4: 判定 | I4: 備考
A5: 1 | B5: 01 選定理由 | C5: 車いす | D5: くるまいすせ | E5: 下肢筋力の低下により自力での移動が困難なため、安全かつスムーズな移動手段として車いすを選定しました。 | F5: 名詞 | G5: =LEN(E5) -> 50 | H5: =IF(G5<=100,"OK","100字超") -> OK | I5: 変更なし
A6: 2 | B6: 01 選定理由 | C6: 車いす | D6: くるまいすせ | E6: 外出時の歩行に不安があり、転倒リスクの軽減と行動範囲の維持・拡大を図るため、車いすを選定しました。 | F6: 名詞 | G6: =LEN(E6) -> 49 | H6: =IF(G6<=100,"OK","100字超") -> OK | I6: 変更なし
A7: 3 | B7: 01 選定理由 | C7: 車いす | D7: くるまいすせ | E7: 長距離の歩行が困難なため、安全な移動を確保するとともに介護者の負担を軽減できるよう、車いすを選定しました。 | F7: 名詞 | G7: =LEN(E7) -> 53 | H7: =IF(G7<=100,"OK","100字超") -> OK | I7: 文章を修正
A8: 4 | B8: 01 選定理由 | C8: 車いす | D8: くるまいすせ | E8: 上肢の力を活かしてご自身で屋内を移動できるよう、操作しやすい自走用の車いすを選定しました。 | F8: 名詞 | G8: =LEN(E8) -> 45 | H8: =IF(G8<=100,"OK","100字超") -> OK | I8: 追加（今回新しく登録）
A9: 5 | B9: 01 選定理由 | C9: 車いす | D9: くるまいすせ | E9: 自力での駆動が難しいため、介助者が押しやすく、安全に移動できる介助用の車いすを選定しました。 | F9: 名詞 | G9: =LEN(E9) -> 46 | H9: =IF(G9<=100,"OK","100字超") -> OK | I9: 追加（今回新しく登録）
A10: 6 | B10: 01 選定理由 | C10: 車いす | D10: くるまいすせ | E10: ベッドや便座への移乗を安全かつスムーズに行えるよう、アームサポートやフットサポートの着脱ができる車いすを選定しました。 | F10: 名詞 | G10: =LEN(E10) -> 59 | H10: =IF(G10<=100,"OK","100字超") -> OK | I10: 追加（今回新しく登録）
A11: 7 | B11: 01 選定理由 | C11: 車いす付属品 | D11: くるまいすふぞくせ | E11: 座位保持の安定を図り、長時間の着座による身体の負担や痛み、姿勢の崩れを防ぐため車いす付属品を選定しました。 | F11: 名詞 | G11: =LEN(E11) -> 53 | H11: =IF(G11<=100,"OK","100字超") -> OK | I11: 文章を修正
A12: 8 | B12: 01 選定理由 | C12: 車いす付属品 | D12: くるまいすふぞくせ | E12: 臀部への圧力を分散して皮膚トラブルや褥瘡のリスクを軽減し、安全かつ安楽に車いすを利用できるよう車いす付属品を選定しました。 | F12: 名詞 | G12: =LEN(E12) -> 61 | H12: =IF(G12<=100,"OK","100字超") -> OK | I12: 文章を修正
A13: 9 | B13: 01 選定理由 | C13: 車いす付属品 | D13: くるまいすふぞくせ | E13: 身体の傾きを補正して適切な座位姿勢を保ち、安全な駆動や食事動作を支援するため車いす付属品を選定しました。 | F13: 名詞 | G13: =LEN(E13) -> 52 | H13: =IF(G13<=100,"OK","100字超") -> OK | I13: 文章を修正
A14: 10 | B14: 01 選定理由 | C14: 車いす付属品 | D14: くるまいすふぞくせ | E14: 座っているうちに前方へずり落ちやすいため、姿勢を安定させ転落を防止できるよう、車いす付属品（クッション）を選定しました。 | F14: 名詞 | G14: =LEN(E14) -> 60 | H14: =IF(G14<=100,"OK","100字超") -> OK | I14: 追加（今回新しく登録）
A15: 11 | B15: 01 選定理由 | C15: 車いす付属品 | D15: くるまいすふぞくせ | E15: 車いすに座ったまま食事や趣味の活動を楽しめるよう、車いす用テーブルを選定しました。 | F15: 名詞 | G15: =LEN(E15) -> 41 | H15: =IF(G15<=100,"OK","100字超") -> OK | I15: 追加（今回新しく登録）
A16: 12 | B16: 01 選定理由 | C16: 車いす付属品 | D16: くるまいすふぞくせ | E16: 坂道や長い距離の移動では介助者の負担が大きいため、楽で安全な移動ができるよう電動補助装置を選定しました。 | F16: 名詞 | G16: =LEN(E16) -> 52 | H16: =IF(G16<=100,"OK","100字超") -> OK | I16: 追加（今回新しく登録）
... A622: 618 | B622: 16 AI指示文・PC用語 | C622: PC用語 | D622: どらど | E622: ドラッグ＆ドロップ | F622: 名詞 | G622: =LEN(E622) -> 9 | H622: =IF(G622<=100,"OK","100字超") -> OK | I622: 変更なし

Sheet よみ早見表
A1: よみ早見表（選定理由・提案理由・留意事項・ケアマネージャーとの相談記録・モニタリング・相談内容）
A2: よみを入力して変換すると、同じよみの文章がすべて候補に出ます。「件数」は辞書一覧から自動で数えています。
A4: ■ 選定理由・留意事項（用具別）
A5: 用具 | B5: 選定理由のよみ | C5: 件数 | D5: 留意事項のよみ | E5: 件数 | F5: 入力のコツ
A6: 車いす | B6: くるまいすせ | C6: =COUNTIF(辞書一覧!$D$5:$D$622,B6) -> 6 | D6: くるまいすりゅ | E6: =COUNTIF(辞書一覧!$D$5:$D$622,D6) -> 6 | F6: 用具名＋「せ」／用具名＋「りゅ」
A7: 車いす付属品 | B7: くるまいすふぞくせ | C7: =COUNTIF(辞書一覧!$D$5:$D$622,B7) -> 6 | D7: くるまいすふぞくりゅ | E7: =COUNTIF(辞書一覧!$D$5:$D$622,D7) -> 6 | F7: 用具名＋「せ」／用具名＋「りゅ」
A8: 特殊寝台 | B8: べっどせ | C8: =COUNTIF(辞書一覧!$D$5:$D$622,B8) -> 6 | D8: べっどりゅ | E8: =COUNTIF(辞書一覧!$D$5:$D$622,D8) -> 6 | F8: 用具名＋「せ」／用具名＋「りゅ」
A9: 特殊寝台付属品 | B9: べっどふぞくせ | C9: =COUNTIF(辞書一覧!$D$5:$D$622,B9) -> 6 | D9: べっどふぞくりゅ | E9: =COUNTIF(辞書一覧!$D$5:$D$622,D9) -> 6 | F9: 用具名＋「せ」／用具名＋「りゅ」
A10: 床ずれ防止用具 | B10: とこずれせ | C10: =COUNTIF(辞書一覧!$D$5:$D$622,B10) -> 6 | D10: とこずれりゅ | E10: =COUNTIF(辞書一覧!$D$5:$D$622,D10) -> 4 | F10: 用具名＋「せ」／用具名＋「りゅ」
A11: 体位変換器 | B11: たいいへんかんきせ | C11: =COUNTIF(辞書一覧!$D$5:$D$622,B11) -> 6 | D11: たいいへんかんきりゅ | E11: =COUNTIF(辞書一覧!$D$5:$D$622,D11) -> 6 | F11: 用具名＋「せ」／用具名＋「りゅ」
A12: 手すり | B12: てすりせ | C12: =COUNTIF(辞書一覧!$D$5:$D$622,B12) -> 10 | D12: てすりりゅ | E12: =COUNTIF(辞書一覧!$D$5:$D$622,D12) -> 6 | F12: 用具名＋「せ」／用具名＋「りゅ」
A13: スロープ | B13: すろーぷせ | C13: =COUNTIF(辞書一覧!$D$5:$D$622,B13) -> 6 | D13: すろーぷりゅ | E13: =COUNTIF(辞書一覧!$D$5:$D$622,D13) -> 6 | F13: 用具名＋「せ」／用具名＋「りゅ」
A14: 歩行器 | B14: ほこうきせ | C14: =COUNTIF(辞書一覧!$D$5:$D$622,B14) -> 10 | D14: ほこうきりゅ | E14: =COUNTIF(辞書一覧!$D$5:$D$622,D14) -> 7 | F14: 用具名＋「せ」／用具名＋「りゅ」
A15: 歩行補助杖 | B15: つえせ | C15: =COUNTIF(辞書一覧!$D$5:$D$622,B15) -> 7 | D15: つえりゅ | E15: =COUNTIF(辞書一覧!$D$5:$D$622,D15) -> 7 | F15: 用具名＋「せ」／用具名＋「りゅ」
A16: 徘徊感知機器 | B16: はいかいかんちきせ | C16: =COUNTIF(辞書一覧!$D$5:$D$622,B16) -> 6 | D16: はいかいかんちきりゅ | E16: =COUNTIF(辞書一覧!$D$5:$D$622,D16) -> 6 | F16: 用具名＋「せ」／用具名＋「りゅ」
A17: 移動用リフト | B17: いどうようりふとせ | C17: =COUNTIF(辞書一覧!$D$5:$D$622,B17) -> 6 | D17: いどうようりふとりゅ | E17: =COUNTIF(辞書一覧!$D$5:$D$622,D17) -> 5 | F17: 用具名＋「せ」／用具名＋「りゅ」
... A21: 浴槽手すり | B21: よくそうてすりせ | C21: =COUNTIF(辞書一覧!$D$5:$D$622,B21) -> 6 | D21: よくそうてすりりゅ | E21: =COUNTIF(辞書一覧!$D$5:$D$622,D21) -> 6 | F21: 用具名＋「せ」／用具名＋「りゅ」
A22: 福祉用具全般（共通） | B22: － | D22: りゅうい | E22: =COUNTIF(辞書一覧!$D$5:$D$622,D22) -> 4 | F22: （福祉用具全般）で始まる共通の文
A24: ■ 提案理由
A25: 用具 | B25: よみ | C25: 件数 | D25: 内容の例（1件目）
A26: 手すり | B26: てすりていあん | C26: =COUNTIF(辞書一覧!$D$5:$D$622,B26) -> 5 | D26: 狭いスペースにも設置でき、移動や立ち座りなど幅広い場面で転倒を予防できるため、突っ張り型の手すりを提案しました。
A28: ■ ケアマネージャーとの相談記録
A29: 会議の種類 | B29: よみ | C29: 件数 | D29: 内容の例（1件目）
A30: 新規 | B30: しんきたんかい | C30: =COUNTIF(辞書一覧!$D$5:$D$622,B30) -> 14 | D30: 新規サービス利用担当者会議。今後の支援内容やサービス利用上の注意点について話し合った。
A31: 中間見直し | B31: ちゅうかんたんかい | C31: =COUNTIF(辞書一覧!$D$5:$D$622,B31) -> 12 | D31: 中間プラン見直し担当者会議
A32: 更新 | B32: こうしんたんかい | C32: =COUNTIF(辞書一覧!$D$5:$D$622,B32) -> 13 | D32: 更新担当者会議
A33: 福祉用具追加 | B33: ついかたんかい | C33: =COUNTIF(辞書一覧!$D$5:$D$622,B33) -> 11 | D33: 福祉用具追加担当者会議
A34: サービス内容変更 | B34: へんこうたんかい | C34: =COUNTIF(辞書一覧!$D$5:$D$622,B34) -> 5 | D34: サービス内容変更担当者会議。サービスの変更点を確認し、今後の支援内容や注意点について説明した。
A35: ケアプラン長期切れ | B35: ちょうきたんかい | C35: =COUNTIF(辞書一覧!$D$5:$D$622,B35) -> 4 | D35: 【ケアプラン長期切れ担当者会議】
A36: 見出し | B36: たんかい | C36: =COUNTIF(辞書一覧!$D$5:$D$622,B36) -> 1 | D36: 担当者会議
A37: 不要・理由の記載 | B37: ちゅうかんふよう | C37: =COUNTIF(辞書一覧!$D$5:$D$622,B37) -> 1 | D37: 中間プラン見直し担当者会議のため、不要。
A38: 不要・理由の記載 | B38: こうしんふよう | C38: =COUNTIF(辞書一覧!$D$5:$D$622,B38) -> 1 | D38: 更新担当者会議のため、不要。
A39: 不要・理由の記載 | B39: にんていふよう | C39: =COUNTIF(辞書一覧!$D$5:$D$622,B39) -> 1 | D39: 認定更新のため、不要。
A40: 不要・理由の記載 | B40: かいほいこう | C40: =COUNTIF(辞書一覧!$D$5:$D$622,B40) -> 1 | D40: 介護保険移行のため。
A42: ■ モニタリング
A43: 記入欄 | B43: よみ | C43: 件数 | D43: 内容の例（1件目）
A44: 利用目標の達成状況 | B44: りもく | C44: =COUNTIF(辞書一覧!$D$5:$D$622,B44) -> 10 | D44: 福祉用具を利用することで、安心・安全な在宅生活や負担軽減につながっています。
A45: 点検結果 | B45: てんけん | C45: =COUNTIF(辞書一覧!$D$5:$D$622,B45) -> 11 | D45: 本日の用具点検でも異常はなく、引き続き安心してご利用いただける状態です。万一の不具合にもすぐに対応いたします。
A46: 身体状況・ADLの変化 | B46: しなし | C46: =COUNTIF(辞書一覧!$D$5:$D$622,B46) -> 10 | D46: 身体状況に大きな変化はありません。
A47: 意欲・意向等の変化 | B47: いなし | C47: =COUNTIF(辞書一覧!$D$5:$D$622,B47) -> 9 | D47: 意欲・意向等に変化はありません。
...

Sheet 変更履歴
A1: 変更履歴（元の6ファイルの全行と、統合版での扱い）
A2: 処理：変更なし／文章修正／よみ統一／統合（完全に同じ・同じ文で別のよみ・表記ゆれ・途中で切れた同じ文・似た内容）／削除。「一覧のNo.」は辞書一覧の番号です。公開用のため、個人情報を含む行は載せていません。
A4: 元ファイル | B4: 行 | C4: 元のよみ | D4: 元の登録内容 | E4: 処理 | F4: 新しいよみ | G4: 新しい登録内容 | H4: 一覧のNo. | I4: 備考
A5: 3.txt | B5: 1 | C5: しゃわーちぇあせ | D5: 浴室での立ち座り動作の負担を軽減し、安定した座位姿勢で身体を洗うことができるようシャワーチェアを選定しました。 | E5: 文章修正 | F5: しゃわーちぇあせ | G5: 浴室での立ち座り動作の負担を軽減し、安定した座位姿勢で身体を洗えるようシャワーチェアを選定しました。 | H5: 88
A6: 3.txt | B6: 2 | C6: しゃわーちぇあせ | D6: 下肢の筋力低下により浴室内の移動や立位保持に不安があるため、転倒を防止し安全に入浴できるようシャワーチェアを選定しました。 | E6: 変更なし | F6: しゃわーちぇあせ | G6: 下肢の筋力低下により浴室内の移動や立位保持に不安があるため、転倒を防止し安全に入浴できるようシャワーチェアを選定しました。 | H6: 89
A7: 3.txt | B7: 3 | C7: しゃわーちぇあせ | D7: 洗い場での滑りによる転倒リスクを軽減し、ご本人の身体状況に合わせた高さで安全に座位を保つためシャワーチェアを選定しました。 | E7: 変更なし | F7: しゃわーちぇあせ | G7: 洗い場での滑りによる転倒リスクを軽減し、ご本人の身体状況に合わせた高さで安全に座位を保つためシャワーチェアを選定しました。 | H7: 90
A8: 3.txt | B8: 4 | C8: よくそうだいせ | D8: 浴槽の底を底上げして跨ぎ動作の負担を軽減し、浴槽内への出入りを安全かつスムーズに行えるよう浴槽台を選定しました。 | E8: 文章修正 | F8: よくそうだいせ | G8: 浴槽内の床面を高くして跨ぎ動作の負担を軽減し、浴槽への出入りを安全かつスムーズに行えるよう浴槽台を選定しました。 | H8: 100
A9: 3.txt | B9: 5 | C9: よくそうだいせ | D9: 浴槽内での立ち座り動作が困難なため、適切な高さで座位を保持し、立ち上がりの動作を安全に補助するために浴槽台を選定しました。 | E9: 文章修正 | F9: よくそうだいせ | G9: 浴槽内での立ち座りが困難なため、適切な高さで座位を保ち、立ち上がりを安全に補助できるよう浴槽台を選定しました。 | H9: 101
A10: 3.txt | B10: 6 | C10: よくそうだいせ | D10: 浴槽内の深い段差を解消することで、足腰への負担を和らげ、浮力によるふらつきを抑えて安全に入浴できるよう浴槽台を選定しました。 | E10: 文章修正 | F10: よくそうだいせ | G10: 浴槽の深さによる段差を解消して足腰への負担を和らげ、浮力によるふらつきを抑えて安全に入浴できるよう浴槽台を選定しました。 | H10: 102
A11: 3.txt | B11: 7 | C11: よくそうてすりせ | D11: 浴槽への出入りを安全に行うための支持点を確保し、跨ぎ動作時のふらつきを抑えて転倒を防止するため浴槽手すりを選定しました。 | E11: 変更なし | F11: よくそうてすりせ | G11: 浴槽への出入りを安全に行うための支持点を確保し、跨ぎ動作時のふらつきを抑えて転倒を防止するため浴槽手すりを選定しました。 | H11: 108
A12: 3.txt | B12: 8 | C12: よくそうてすりせ | D12: 浴槽内での立ち座り動作を補助し、滑りやすい浴室環境下でもしっかりと身体を支え、安全に入浴できるよう浴槽手すりを選定しました。 | E12: 文章修正 | F12: よくそうてすりせ | G12: 浴槽内での立ち座りを補助し、滑りやすい浴室でもしっかりと身体を支えて安全に入浴できるよう浴槽手すりを選定しました。 | H12: 109
A13: 3.txt | B13: 9 | C13: よくそうてすりせ | D13: 姿勢の安定を図り、浴槽への出入りや浴槽内での姿勢保持を安全に行うことで、水場での事故を未然に防ぐため浴槽手すりを選定しました。 | E13: 文章修正 | F13: よくそうてすりせ | G13: 浴槽への出入りや浴槽内での姿勢保持を安全に行えるようにし、水まわりでの事故を未然に防ぐため浴槽手すりを選定しました。 | H13: 110
A14: 3.txt | B14: 10 | C14: ぽーたぶるといれせ | D14: 夜間等、トイレまでの移動が困難な場合に、安全に排泄が行える環境を整えるため選定しました。 | E14: 文章修正 | F14: ぽーたぶるといれせ | G14: 夜間などトイレまでの移動が困難な場合でも、安全に排泄できる環境を整えるためポータブルトイレを選定しました。 | H14: 82
A15: 3.txt | B15: 11 | C15: ぽーたぶるといれせ | D15: 居室内で安全に排泄動作を行うことで、転倒リスクを軽減し、心理的な負担を和らげるため選定しました。 | E15: 文章修正 | F15: ぽーたぶるといれせ | G15: 居室内で安全に排泄できるようにすることで転倒リスクを軽減し、心理的な負担を和らげるためポータブルトイレを選定しました。 | H15: 83
A16: 3.txt | B16: 12 | C16: ぽーたぶるといれせ | D16: 身体状況に合わせて最適な高さで排泄動作を支援し、自立した生活を継続するため選定しました。 | E16: 文章修正 | F16: ぽーたぶるといれせ | G16: 身体状況に合わせた高さで排泄動作を支援し、自立した生活を継続できるようポータブルトイレを選定しました。 | H16: 84
... A99: 3.txt | B99: 95 | C99: ほこうきせ | D99: 握力低下や手首の痛みにより杖等を握ることが困難なため、腕全体で体重を支えることで身体負荷を軽減し、安全に移動するために選定しました。 | E99: 文章修正 | F99: ほこうきせ | G99: 握力の低下や手首の痛みで杖等を握ることが難しいため、腕全体で体重を支えて負担を軽減し、安全に移動できるよう前腕支持型の歩行器を選定しました。 | H99: 59
A100: 4.txt | B100: 1 | E100: 削除 | I100: 空行（よみ・内容なし）
A101: 4.txt | B101: 2 | C101: よくそうだいせんてい | D101: 下肢筋力の低下により浴槽の出入りが困難となっているため、高さ調整可能な浴槽台を使用し、立ち座り動作や浴槽への跨ぎ動作の安定性を確保し転倒リスクを軽減するため、選定しました。 | E101: よみ統一・文章修正 | F101: よくそうだいせ | G101: 下肢筋力の低下により浴槽の出入りが困難なため、高さ調整が可能な浴槽台で立ち座りや跨ぎ動作を安定させ、転倒リスクを軽減できるよう選定しました。 | H101: 103
A102: 4.txt | B102: 3 | C102: よくそうだい | D102: 浴槽台 | E102: 変更なし | F102: よくそうだい | G102: 浴槽台 | H102: 452
A103: 4.txt | B103: 4 | C103: よくそうだいりゅうい | D103: 浴槽台は床にしっかりと固定されているか確認し、安定した場所に設置することが必要です。不安定な場所に置くと転倒の恐れがあります | E103: 統合（似た内容） | F103: よくそうだいりゅ | G103: （浴槽台）浴槽内に置く際は、吸盤をしっかり押し付けて固定してからご使用ください。不安定なまま使うと転倒のおそれがあります。 | H103: 204
A104: 4.txt | B104: 5 | C104: FS | D104: シャワーベンチを利用する事で、入浴時の立ち座りや座位保持の安定に繋がるため、選定しました。 | E104: よみ統一・文章修正 | F104: しゃわーちぇあせ | G104: シャワーベンチを使用することで、入浴時の立ち座りや座位保持が安定するため選定しました。 | H104: 95
A105: 4.txt | B105: 6 | C105: えふえす | D105: シャワーベンチを利用する事で、入浴時の立ち座りや座位保持の安定に繋がるため、選定しました。 | E105: 統合（同じ文・別のよみ） | F105: しゃわーちぇあせ | G105: シャワーベンチを使用することで、入浴時の立ち座りや座位保持が安定するため選定しました。 | H105: 95
A106: 4.txt | B106: 7 | C106: しゃわーせんてい | D106: 入浴時の立ち座りや座位保持の安定のため、選定しました。動作の安全のため、ひじ掛け跳ね上げ付きのシャワーチェアを選定。 | E106: よみ統一・文章修正 | F106: しゃわーちぇあせ | G106: 入浴時の立ち座りや座位保持を安定させ、動作を安全に行えるよう、ひじ掛け跳ね上げ付きのシャワーチェアを選定しました。 | H106: 92
A107: 4.txt | B107: 8 | C107: しゃわーりゅうい | D107: （シャワーベンチ）折りたたみや高さ調整時には注意し、利用してください。 | E107: よみ統一・文章修正 | F107: しゃわーちぇありゅ | G107: （シャワーチェア）折りたたみや高さ調整の際は、指を挟まないよう十分ご注意ください。 | H107: 199
A108: 4.txt | B108: 9 | C108: しゃわーちぇありゅうい | D108: （シャワーチェアー）足裏のゴムなど、商品の不具合を感じた際はすぐにご連絡ください。 | E108: 統合（似た内容） | F108: しゃわーちぇありゅ | G108: （シャワーチェア）石けんの泡や汚れで滑りやすくなりますのでご注意ください。脚ゴムのすり減り等はモニタリング時に点検します。不具合を感じた際は、すぐに担当者までご連絡ください。 | H108: 197
A109: 4.txt | B109: 10 | C109: とこずれりゅうい | D109: （床ずれ防止用具）マットレスのへたりを感じた際は交換致しますので、ご連絡下さい。 | E109: よみ統一・文章修正 | F109: とこずれりゅ | G109: （床ずれ防止用具）マットレスの状態はモニタリング時に担当者が確認します。へたりを感じた際は交換しますので、担当者までご連絡ください。 | H109: 143
A110: 4.txt | B110: 11 | C110: よんてんつえりゅうい | D110: （歩行補助杖）グリップ部分の摩耗や杖ゴムの劣化が生じた際は、交換致します。 | E110: よみ統一・文章修正 | F110: つえりゅ | G110: （歩行補助杖）杖先ゴムやグリップのすり減り・破れに気づいた際は、交換しますので担当者までご連絡ください。 | H110: 173
A111: 4.txt | B111: 12 | C111: よんてんりゅうい | D111: (四点杖）四点杖を利用する際は、杖ゴムやグリップ部分の劣化にご注意ください。摩耗がみられた際には交換致します。 | E111: 統合（似た内容） | F111: つえりゅ | G111: （歩行補助杖）杖先ゴムやグリップのすり減り・破れに気づいた際は、交換しますので担当者までご連絡ください。 | H111: 173
A112: 4.txt | B112: 13 | C112: りゅうい | D112: ※商品に不調等の問題がある場合は事故や怪我の原因となりますので、ご連絡下さい。 | E112: 文章修正 | F112: りゅうい | G112: （福祉用具全般）商品に不調がある状態で使い続けると、事故やけがの原因となります。異常を感じた際は使用を中止し、担当者までご連絡ください。 | H112: 215
... A124: 5.txt | B124: 12 | C124: さなし | D124: 現在ご利用中のサービスやご自宅の環境について、変わりなく継続されています。 | E124: 文章修正 | F124: さなし | G124: 現在ご利用中のサービスやご自宅の環境に変わりはなく、継続されています。 | H124: 332
A125: 5.txt | B125: 13 | C125: さなし | D125: 家族状況に大きな変化はありません。 | E125: 統合（同じ文・別のよみ） | F125: かなし | G125: 家族状況に大きな変化はありません。 | H125: 323 | I125: 家族状況の文が「さなし」（サービス欄）に登録されていたため、「かなし」に統合
A126: 5.txt | B126: 14 | C126: さなし | D126: ご家族の介護状況に変化はありません。 | E126: 統合（同じ文・別のよみ） | F126: かなし | G126: ご家族の介護状況に変化はありません。 | H126: 324 | I126: 家族状況の文が「さなし」（サービス欄）に登録されていたため、「かなし」に統合
A127: 5.txt | B127: 15 | C127: よくそうてすりりゅうい | D127: （浴槽手すり）グリップが淵にしっかりと固定されていることや緩みがないか確認したうえで使用されてください。 | E127: 統合（似た内容） | F127: よくそうてすりりゅ | G127: （浴槽手すり）浴槽縁への固定状態や締め付けノブの緩みは、モニタリング時に担当者が点検します。ぐらつきを感じた際は使用を中止し、担当者までご連絡ください。 | H127: 209
A128: 6.txt | B128: 1 | C128: れんほう | D128: レンタル単位数報告書 | E128: 変更なし | F128: れんほう | G128: レンタル単位数報告書 | H128: 402
A129: 6.txt | B129: 2 | C129: れんたん | D129: レンタル単位数 | E129: 変更なし | F129: れんたん | G129: レンタル単位数 | H129: 401
A130: 6.txt | B130: 3 | C130: りようもくひょう | D130: 福祉用具を利用する事で、安心・安全な在宅生活や負担軽減に繋がっています。 | E130: 統合（同じ文・別のよみ） | F130: りもく | G130: 福祉用具を利用することで、安心・安全な在宅生活や負担軽減につながっています。 | H130: 283
A131: 6.txt | B131: 5 | C131: りもく | D131: 福祉用具を利用する事で、安心・安全な在宅生活や負担軽減に繋がっています。 | E131: 文章修正 | F131: りもく | G131: 福祉用具を利用することで、安心・安全な在宅生活や負担軽減につながっています。 | H131: 283
A132: 6.txt | B132: 6 | C132: りも | D132: 福祉用具を利用することで身体に負担をかけることなく安全安楽に在宅生活が送れ、負担軽減に繋がっています。 | E132: よみ統一・文章修正 | F132: りもく | G132: 福祉用具を利用することで、身体に負担をかけず安全・安楽に在宅生活が送れ、負担軽減につながっています。 | H132: 284
A133: 6.txt | B133: 7 | C133: りぷらす | D133: ケアプランセンター リプラス | E133: 変更なし | F133: りぷらす | G133: ケアプランセンター リプラス | H133: 557
A134: 6.txt | B134: 8 | C134: りぷらす | D134: ケアプランセンターリプラス | E134: 統合（表記ゆれ） | F134: りぷらす | G134: ケアプランセンター リプラス | H134: 557
...

Sheet 使い方・ルール
A1: 使い方・登録ルール
A3: 1. このファイルについて
B4: 内容 | C4: 福祉用具貸与の計画書・記録で使う文章（選定理由・提案理由・留意事項・ケアマネージャーとの相談記録・モニタリング・相談内容）と、事業所名・定型文などの辞書登録を1つにまとめた一覧です。
B5: 元のファイル | C5: 3.txt／4.txt／5.txt／6.txt／7.txt／修正 モニタリング・計画書辞書.txt（計696行）
B6: まとめた結果 | C6: 元の696行を523件に整理（重複・類似 164行を統合、空行 9行を削除）し、新しい文・単語を 164件追加して、全687件。公開用のため、個人情報を含む 69件を除いた618件を載せています。
B7: 追加した文 | C7: 選定理由・留意事項は各用具に3件ずつ、提案理由（手すり）に3件、ケアマネージャーとの相談記録は各種類に3件ずつ、モニタリングは各記入欄に3件ずつ、相談内容に3件を追加しました。商品名は ゆくえあ（シャワーチェア（Air）ミドルSPワンタッチ）、ゆくこん（シャワーチェア（Air）コンパクトSPワンタッチ） を登録しました。辞書一覧の備考欄に「追加」と表示しています（変更履歴には載りません）。
B8: 取り込み用ファイル | C8: このExcelと同じ名前の .txt ファイル（UTF-8・タブ区切り：よみ／登録する言葉／品詞／コメント）。コメント欄には「選定理由（手すり）」のように分類が入るので、辞書ツールで見ても何の文章か分かります。
A10: 2. Google日本語入力への取り込み方
B11: 手順1 | C11: タスクバーの「あ」（または「A」）を右クリック →「辞書ツール」を開く。
B12: 手順2 | C12: 念のため、今の辞書を選んで「管理」→「選択した辞書をエクスポート」でバックアップする。
B13: 手順3 | C13: 「管理」→「新規辞書にインポート」→ 取り込み用 .txt を選ぶ → 辞書名（例：福祉用具辞書）を入れて「インポート」。
B14: 手順4 | C14: 古い辞書（3〜7.txt・修正版を取り込んだもの）は「管理」→「選択した辞書を削除」で削除する。残したままだと、同じ候補が二重に出たり、旧よみで古い文章が出たりします。
A16: 3. よみのルール
B17: 選定理由 | C17: 用具名＋「せ」 例：てすりせ／しゃわーちぇあせ／べっどせ
B18: 提案理由 | C18: 用具名＋「ていあん」 例：てすりていあん（「〜を提案しました。」で終わる文）
B19: 留意事項 | C19: 用具名＋「りゅ」 例：てすりりゅ／しゃわーちぇありゅ／べっどりゅ （福祉用具全般の共通の文は「りゅうい」）
B20: ケアマネージャーとの相談記録 | C20: しんきたんかい（新規）／ちゅうかんたんかい（中間見直し）／こうしんたんかい（更新）／ついかたんかい（福祉用具追加）／へんこうたんかい（サービス内容変更）／ちょうきたんかい（長期切れ）
B21: モニタリング | C21: りもく（利用目標）／てんけん（点検結果）／しなし（身体・ADL）／いなし（意欲・意向）／かなし（家族）／さなし（サービス利用）／じゅうかんきょう（住環境）／ひょうか（総合評価）／てきぎ（今後の方針）／こんけい（継続の必要性）／しんきのうひん・ついかのうひん（納品後の初回）
B22: 相談内容 | C22: そうだんきろく（ご本人の言葉）
B23: その他 | C23: 事業所名・人名・定型文などのよみは、これまでどおりです（よみ早見表の「旧よみ → 新しいよみ」も参照）。
A25: 4. 文章のルール（誰から誰への文章か）
B26: 選定理由 | C26: 担当者（福祉用具専門相談員）が、ご本人・ご家族・ケアマネジャーに向けて選定の理由を説明する文。「〜のため、〇〇を選定しました。」の形にそろえています。
B27: 提案理由 | C27: 担当者が、ご本人・ご家族・ケアマネジャーに用具や手すりの設置を提案する理由を説明する文。選定理由とは分けて、「〜のため、〇〇を提案しました。」の形にしています。
B28: 留意事項 | C28: 用具の点検（ロックピン・ゴムの摩耗・固定の緩みなど）は、モニタリング時に担当者が行います。ご本人・ご家族にお願いするのは「使うときの注意」と「ぐらつき等の異常を感じたら担当者へ連絡」の2点です。すべての文の先頭に（手すり）（シャワーチェア）（床ずれ防止用具）のように用具名を付けています。全用具に共通の文は（福祉用具全般）で始まります。
B29: ケアマネージャーとの相談記録 | C29: 担当者会議などで、ケアマネージャーや関係者と相談・確認した内容を担当者が記録する文（です・ます調）。「更新担当者会議。〜」で始まる短い文は、である調のメモ用です。
B30: モニタリング | C30: 担当者がモニタリングの結果をケアマネジャー等へ報告・記録する文。
B31: 相談内容 | C31: ご本人が担当者に話した言葉として、へりくだり過ぎない自然な話し言葉にしています。
B32: 表記 | C32: 「ください」「いたします」「つながる」「できる」「こと」はひらがなで統一しています。
A34: 5. 100文字のルール
B35: 上限 | C35: Google日本語入力は1語あたり最大300バイト（全角で100文字）まで。超えた分は登録できない・切れてしまいます。元のファイルには60文字・100文字で途中から切れていた文があったため、文末まで補ったうえで100文字以内に直しています。
B36: 確認方法 | C36: 「辞書一覧」の「文字数」「判定」列で確認できます（書き換えると自動で再計算され、100文字を超えると赤くなります）。
